Workbook

Sheet BOM A320 FFS
A1: EDT | B1: CODIGO INDRA | C1: REF HW | D1: Alternativo | E1: Alternativo RS | F1: DESCRIPCIÓN MATERIAL | G1: P/N FABRICANTE | H1: FABRICANTE | I1: PROVEEDOR | J1: QTY | K1: P.U.
A2: DATA PACKAGE, SW PACKAGE, LICENCIAS | F2: A320 neo std 2.0.0 Simpack | H2: AIRBUS | I2: AIRBUS GO5 | J2: 1 | K2: 2578500
A3: CABINA | F3: Hardware Package | H3: AIRBUS | I3: AIRBUS GO5 | J3: 1 | K3: 1140000
A4: SISTEMA DE MOVIMIENTO | B4: 1390705229900 | F4: MOTION KIT,3RD GEN,MB-E-6DOF-60.0-14000KG | G4: CC91958-000A-075-0 | H4: MOOG | I4: MOOG | J4: 1 | K4: 480000
A5: CABINA | F5: EQUIP SE1 FCU/3XRPM/ATC/BPI/DDRMI/ISIS | H5: THALES | I5: THALES | J5: 1 | K5: 223899.6
A6: BASEFRAME Y AFTCABIN | F6: FABRICACION BASE FRAME Y AFTER CABIN | H6: TALLERES XUQUER, SL | I6: TALLERES XUQUER, SL | J6: 1 | K6: 180000
A7: DATA PACKAGE, SW PACKAGE, LICENCIAS | B7: 3166035600000 | C7: N/A | D7: N/A | E7: N/A | F7: HONEYWELL LIC SW SIMULADOR FMS A320 FFS | G7: PS4087600-907 | H7: HONEYWELL | I7: HONEYWELL | J7: 1 | K7: =#REF!*#REF! -> #REF!
A8: DATA PACKAGE, SW PACKAGE, LICENCIAS | B8: 3166097300005 | F8: LIC SW FG FUNCTION ROYALTY/SIM C/DONGLE | H8: THALES | I8: THALES | J8: 1 | K8: 108814
A9: DATA PACKAGE, SW PACKAGE, LICENCIAS | B9: 3166097300007 | F9: LIC SW EIS 2 FUNCTION REPLICATION FEE | H9: THALES | I9: THALES | J9: 1 | K9: 99704
A10: DATA PACKAGE, SW PACKAGE, LICENCIAS | B10: 1390700590500 | F10: EGPWC A320 STD 2.0 - Simulado | G10: 69000942-151 | H10: HONEYWELL | I10: HONEYWELL | J10: 1 | K10: 82800
A11: SISTEMA DE CONTROL DE FUERZAS | B11: TBD | F11: CLS A320 | G11: CA55977-049 | H11: MOOG | I11: MOOG | J11: 1 | K11: 82432
A12: BASEFRAME Y AFTCABIN | B12: 8570100000000 | F12: MODIFICACIONES BASEFRAME Y AFTERCABIN 2018-2024 | H12: TALLERES XUQUER, SL | I12: TALLERES XUQUER, SL | J12: 1 | K12: 69500
A13: DATA PACKAGE, SW PACKAGE, LICENCIAS | B13: 1390700590501 | C13: N/A | D13: N/A | E13: N/A | F13: HONEYWELL SISTEMA EGPWS MKVA 115VAC P/A320/330/340 | I13: HONEYWELL | J13: 1 | K13: =#REF!*#REF! -> #REF!
A14: DISPLAY | B14: 1390701501301 | F14: Soporte Espejo | G14: 0712061000001 | H14: XUQUER | I14: XUQUER | J14: 1 | K14: 60665
A15: DISPLAY | B15: 0973585290100 | C15: A0301 | F15: SOPORTE ESPEJO | H15: XUQUER | I15: XUQUER | J15: 1 | K15: 60665
A16: DATA PACKAGE, SW PACKAGE, LICENCIAS | B16: 3166097300006 | F16: LIC SW FG FUNCTION STANDARD FEE | H16: THALES | I16: THALES | J16: 1 | K16: 59792
A17: CABINA | F17: DCDU | G17: 401MFD4-3 | H17: GE AVIATION / SYSTEMS LTD | I17: GE AVIATION / SYSTEMS LTD | J17: 2 | K17: 44400
A18: DISPLAY | B18: 1390701501308 | F18: BPS matizada 40 | G18: 0712064000001 | H18: XUQUER | I18: XUQUER | J18: 1 | K18: 38605
A19: DISPLAY | B19: 0973585290800 | C19: A0308 | F19: BPS MATIZADA | H19: XUQUER | I19: XUQUER | J19: 1 | K19: 38605
A20: DATA PACKAGE, SW PACKAGE, LICENCIAS | F20: A320 Std 2.1.0 HW Update Kit without TOS Option | H20: AIRBUS | I20: AIRBUS GO5 | J20: 1 | K20: 35000
A21: DISPLAY | B21: 3140301350000 | F21: PROYECTOR LED DLP 4K UHD P10 WQXGA | G21: 101-1112 | H21: NORXE | I21: NORXE | J21: 3 | K21: 33000
A22: COCKPIT | F22: FABRICACION CABINA COMPLETA | H22: TALLERES XUQUER, SL | I22: TALLERES XUQUER, SL | J22: 1 | K22: 29390.4
A23: SISTEMAS AUXILIARES | B23: 1264011783500 | F23: UPS | G23: GVSUPS80KHS/221213-12728957 | H23: Schneider Electric | I23: SCHNEIDER ELECTRIC | J23: 1 | K23: 25000
A24: DISPLAY | B24: 1390701501306 | F24: Panel Posterior | G24: 0712062000001 | H24: XUQUER | I24: XUQUER | J24: 1 | K24: 19854
A25: DISPLAY | B25: 0973585290600 | C25: A0306 | F25: PANEL POSTERIOR | H25: XUQUER | I25: XUQUER | J25: 1 | K25: 19854
A26: CABINA | B26: 1390701500700 | F26: MCDU | G26: GR-SEQ27901 | H26: GRABYSUR | I26: GRABYSUR | J26: 2 | K26: 19200
A27: SISTEMAS AUXILIARES | B27: 0972825430000.00 / TBD | F27: POWER RACK | G27: 0972825430000.00 / TBD | H27: ISC / INDRA | I27: ISC /AEMSYS | J27: 1 | K27: 19000
A28: CABINA | B28: 9999000322010 | F28: DU NO REC | H28: GRABYSUR | I28: GRABYSUR | J28: 1 | K28: 18000
A29: DISPLAY | B29: 1390701501302 | F29: Cierre superior | G29: 0918686422200 | H29: XUQUER | I29: XUQUER | J29: 1 | K29: 16655
A30: DISPLAY | B30: 0973585290200 | C30: A0302 | F30: CIERRE SUPERIOR | H30: XUQUER | I30: XUQUER | J30: 1 | K30: 16655
A31: DISPLAY | B31: 1390701501307 | F31: Estructura de proyectores, bandejas de proyectores y soportes mascaras | G31: 0712063000001 | H31: XUQUER | I31: XUQUER | J31: 1 | K31: 13236
A32: DISPLAY | B32: 0973585290700 | C32: A0307 | F32: ESTRUCTURA PROY BANDEJA PROY SOPORT MASC | H32: XUQUER | I32: XUQUER | J32: 1 | K32: 13236
A33: DISPLAY | B33: 1390701501304 | F33: Cierre Posterior Superior + Anillo adaptación | G33: 0913385042700 | H33: XUQUER | I33: XUQUER | J33: 1 | K33: 11802
A34: DISPLAY | B34: 0973585290400 | C34: A0304 | F34: CIERRE POST SUP + ANILLOS ADAPT | H34: XUQUER | I34: XUQUER | J34: 1 | K34: 11802
A35: SISTEMA DE MOVIMIENTO | B35: 1390701501200 | F35: PASARELA | G35: 0712100000001 | H35: TALLERES XUQUER, SL | I35: TALLERES XUQUER, SL | J35: 1 | K35: 10108.8
A36: ASIENTO IOS | B36: 1390705801395 | F36: FFIOS PANEL A320 | G36: GR-SEQ40411 | H36: GRABYSUR | I36: GRABYSUR | J36: 1 | K36: 8150.76
A37: DISPLAY | B37: 1390701501303 | F37: Soporte pantalla bps | G37: 0918686423300 | H37: XUQUER | I37: XUQUER | J37: 1 | K37: 7941
A38: DISPLAY | B38: 0973585290300 | C38: A0303 | F38: SOPORTE PANTALLA BPS | H38: XUQUER | I38: XUQUER | J38: 1 | K38: 7941
A39: COMPUTADORES | B39: 3010201822301 | F39: ORDENADOR ENRACABLE Z4 RTXA6000 (GAMA HIGH PC - TIPO IG) | G39: 52258736/7178862 | H39: HP | I39: HP /DELL / SUPERMICRO | J39: 5 | K39: 7000
A40: SISTEMAS AUXILIARES | B40: 1264611110000 | F40: Convertidor 115Vac 400Hz | G40: LF3-400 | H40: MAGNUS POWER | I40: ENELEC | J40: 1 | K40: 7000
...

Sheet EDTs
A1: PROYECTO | B1: A320 FFS GT6 | C1: S24B05
A3: Materiales
A4: S1071 | B4: DISPLAY
A5: S1072 | B5: COCKPIT
A6: S1073 | B6: BASEFRAME-AFTERCABIN
A7: S1074 | B7: ALIMENTACIONES-INTERCONEXIONES
A8: S1075 | B8: EQUIPOS AUXILIARES
A9: S1076 | B9: EQUIPOS CABINA
A10: S1077 | B10: DACS
A11: S1078 | B11: HOST
A12: S1079 | B12: RTIO-AVICOM
A13: S107A | B13: DBS
A14: S107B | B14: IOS-INSE
A15: S107C | B15: MOTION
... A19: S107G | B19: TOOLS
B88: 1501216016001 | G88: DIN 7985 M6x16-A2-70
B89: 1540116000001 | G89: DIN 125 6.4-A2-70
B90: 1540216000101 | G90: DIN 127 B6-A2-70
B91: 1531215000001 | G91: DIN 985 M5-A2-70
B92: 1540115000001 | G92: DIN 125 5.3-A2-70
B796: 1208000320301 | F796: CNC RED 3P/M AER IEC320 10A 250VAC NYLON | G796: PX0686 | J796: 2 | N796: 1 | Q796: 45737 | T796: 2 | X796: 111 | Z796: adalvarezm | AB796: 2

Sheet obsoleta
A1: CHECK | B1: CHECK | C1: EDT | D1: CODIGO INDRA | E1: Alternativo | F1: DESCRIPCIÓN MATERIAL | G1: P/N FABRICANTE | H1: FABRICANTE | I1: PROVEEDOR | J1: QTY | K1: P.U. | L1: IMPORTE | M1: MON | N1: CAMBIO | O1: IMPORTE | P1: 2. CONGELADO (TODO OK) 1. CERRADO PARA LOI (PUEDE HABER PEQUEÑOS CAMBIOS) 3. ABIERTO | Q1: FREEZING DATE | R1: Acopiado SI/NO | S1: NOTAS | T1: PRIORIDAD | U1: LLTI | V1: NOTAS2 | W1: EDT | X1: Contraseña GPI | Y1: SOLICTUD LOTE | Z1: SOLICITANTE | AA1: CHECK | AB1: QTY PEDIDO
A2: SICA | B2: QTY | L2: DIVISA | O2: EUR
C3: S24B05
D4: CABINA
D5: EQUIPOS
A6: =IF(EXACT('BOM A320 FFS'!B6,obsoleta!D6),"OK","ERROR") -> OK | C6: CABINA | F6: DCDU | G6: 401MFD4-3 | H6: GE AVIATION / SYSTEMS LTD | I6: GE AVIATION / SYSTEMS LTD | J6: 2 | K6: 44400 | L6: 88800 | M6: USD | N6: 0.85 | O6: 75480 | P6: N/A | Q6: N/A | R6: N/A | S6: OPCIÓN NO ATSU - NO SE COMPRAN | T6: 1 | W6: S1076 | AA6: ok
A7: =IF(EXACT('BOM A320 FFS'!B7,obsoleta!D7),"OK","ERROR") -> ERROR | C7: DATA PACKAGE, SW PACKAGE, LICENCIAS | D7: 1390700590500 | F7: EGPWC A320 STD 2.0 - Simulado | G7: 69000942-151 | H7: HONEYWELL | I7: HONEYWELL | J7: 1 | K7: 82800 | L7: 82800 | M7: USD | N7: 0.85 | O7: 70380 | P7: CONGELADO | Q7: 45453 | R7: NO | S7: SUBCONTRATO | T7: 3 | W7: S104 | AA7: ok
A8: =IF(EXACT('BOM A320 FFS'!B8,obsoleta!D8),"OK","ERROR") -> ERROR | C8: CABINA | D8: 1279901170900 | F8: COMPASS | G8: 10-7133 CFG 01 | H8: SIMTEK | I8: SIMTEK | J8: 1 | K8: 4800 | L8: 4800 | M8: USD | N8: 0.85 | O8: 4080 | P8: CONGELADO | Q8: 45453 | R8: NO | T8: 1 | U8: SI | W8: S1076 | X8: JA2587/1001 | Y8: 1 | Z8: rochoa | AA8: ok | AB8: 1
A9: =IF(EXACT('BOM A320 FFS'!B10,obsoleta!D9),"OK","ERROR") -> ERROR | C9: CABINA | F9: DU | G9: TBD | H9: GRABYSUR | I9: GRABYSUR | J9: 6 | K9: 16800 | L9: 100800 | M9: USD | N9: 0.85 | O9: 85680 | P9: CERRADO | Q9: 45442 | R9: NO | S9: GRABYSUR - NREC Es hablar con ellos | T9: 1 | U9: SI | W9: S1076 | AA9: ok
A10: =IF(EXACT('BOM A320 FFS'!B11,obsoleta!D10),"OK","ERROR") -> ERROR | C10: CABINA | F10: DU NO REC | H10: GRABYSUR | I10: GRABYSUR | J10: 1 | K10: 18000 | L10: 18000 | M10: USD | N10: 0.85 | O10: 15300 | P10: CERRADO | Q10: 45442 | R10: NO | S10: GRABYSUR - NREC Es hablar con ellos | T10: 1 | U10: SI | W10: S1076 | AA10: ok
A11: =IF(EXACT('BOM A320 FFS'!B12,obsoleta!D11),"OK","ERROR") -> ERROR | C11: CABINA | D11: 1390701500700 | F11: MCDU | G11: GR-SEQ27901 | H11: GRABYSUR | I11: GRABYSUR | J11: 2 | K11: 19200 | L11: 38400 | M11: USD | N11: 0.85 | O11: 32640 | P11: CONGELADO | Q11: 45453 | R11: NO | S11: GRABYSUR | T11: 1 | U11: SI | W11: S1076 | X11: JA2587/1001 | Y11: 1 | Z11: rochoa | AA11: ok | AB11: 2
A12: =IF(EXACT('BOM A320 FFS'!B17,obsoleta!D12),"OK","ERROR") -> OK | AA12: ok
A13: =IF(EXACT('BOM A320 FFS'!B20,obsoleta!D13),"OK","ERROR") -> ERROR | D13: AIRBUS | F13: PARTE INCLUIDO EN EL SIM PACK | AA13: ok
A14: =IF(EXACT('BOM A320 FFS'!B21,obsoleta!D14),"OK","ERROR") -> ERROR | C14: DATA PACKAGE, SW PACKAGE, LICENCIAS | F14: A320 neo std 2.1.0 Simpack | H14: AIRBUS | I14: AIRBUS GO5 | J14: 1 | K14: 2578500 | L14: 2578500 | M14: EUR | N14: 1 | O14: 2578500 | P14: CONGELADO | R14: SI | S14: SUBCONTRATO | T14: 1 | W14: S103 | AA14: ok
A15: =IF(EXACT('BOM A320 FFS'!B22,obsoleta!D15),"OK","ERROR") -> OK | F15: A320 Std 2.1.0 HW Update Kit HAL Option | H15: AIRBUS | I15: AIRBUS GO5 | J15: 1 | K15: 35000 | L15: 35000 | M15: USD | N15: 0.85 | O15: 29750 | P15: ABIERTO | R15: NO | W15: S103 | AA15: ok
A16: =IF(EXACT('BOM A320 FFS'!B23,obsoleta!D16),"OK","ERROR") -> ERROR | C16: CABINA | F16: Hardware Package | H16: AIRBUS | I16: AIRBUS GO5 | J16: 1 | K16: 1140000 | L16: 1140000 | M16: USD | N16: 0.85 | O16: 969000 | P16: CONGELADO | R16: SI | S16: SUBCONTRATO | T16: 1 | U16: SI | W16: S1076 | AA16: ok
A17: =IF(EXACT('BOM A320 FFS'!B24,obsoleta!D17),"OK","ERROR") -> ERROR | AA17: =IF(AC17>AB17,"falta","ok") -> ok
A18: =IF(EXACT('BOM A320 FFS'!B25,obsoleta!D18),"OK","ERROR") -> ERROR | D18: THALES SE1 | AA18: ok
A19: =IF(EXACT('BOM A320 FFS'!B26,obsoleta!D19),"OK","ERROR") -> ERROR | C19: CABINA | F19: EQUIP SE1 FCU/3XRPM/ATC/BPI/DDRMI/ISIS | H19: THALES | I19: THALES | J19: 1 | K19: 223899.6 | L19: 223899.6 | M19: EUR | N19: 1 | O19: 223899.6 | P19: CONGELADO | R19: SI | S19: SUBCONTRATO | T19: 1 | W19: S1076 | AA19: ok
A20: =IF(EXACT('BOM A320 FFS'!B27,obsoleta!D20),"OK","ERROR") -> ERROR | C20: DATA PACKAGE, SW PACKAGE, LICENCIAS | F20: FG FUNCTION - Royalty per simulator | H20: THALES | I20: THALES | J20: 1 | K20: 92911.2 | L20: 92911.2 | M20: EUR | N20: 1 | O20: 92911.2 | P20: CONGELADO | Q20: 45453 | R20: NO | S20: SUBCONTRATO | T20: 2 | W20: S104 | AA20: ok
A21: =IF(EXACT('BOM A320 FFS'!B28,obsoleta!D21),"OK","ERROR") -> ERROR | C21: DATA PACKAGE, SW PACKAGE, LICENCIAS | F21: FG FUNCTION - Version Royalty per simulator | H21: THALES | I21: THALES | J21: 1 | K21: 52840.8 | L21: 52840.8 | M21: EUR | N21: 1 | O21: 52840.8 | P21: CONGELADO | Q21: 45453 | R21: NO | S21: SUBCONTRATO | T21: 2 | W21: S104 | AA21: ok
A22: =IF(EXACT('BOM A320 FFS'!B29,obsoleta!D22),"OK","ERROR") -> ERROR | AA22: ok
A23: =IF(EXACT('BOM A320 FFS'!B33,obsoleta!D23),"OK","ERROR") -> ERROR | D23: CABINA MEC | AA23: ok
A24: =IF(EXACT('BOM A320 FFS'!B34,obsoleta!D24),"OK","ERROR") -> ERROR | C24: COCKPIT | F24: DISEÑO ESTRUCTURA CUADERNAS | H24: TALLERES XUQUER, SL | I24: TALLERES XUQUER, SL | J24: 1 | K24: 3016 | L24: 3619.2 | M24: EUR | N24: 1 | O24: 3619.2 | P24: CONGELADO | R24: SI | S24: SUBCONTRATO | T24: 1 | U24: SI | W24: S1072 | AA24: ok
A25: =IF(EXACT('BOM A320 FFS'!B35,obsoleta!D25),"OK","ERROR") -> ERROR | C25: COCKPIT | F25: FABRICACION CABINA COMPLETA | H25: TALLERES XUQUER, SL | I25: TALLERES XUQUER, SL | J25: 1 | K25: 29390.4 | L25: 35268.48 | M25: EUR | N25: 1 | O25: 35268.48 | P25: CONGELADO | R25: SI | S25: SUBCONTRATO | T25: 1 | U25: SI | W25: S1072 | AA25: ok
A26: =IF(EXACT('BOM A320 FFS'!B36,obsoleta!D26),"OK","ERROR") -> ERROR | C26: COCKPIT | F26: FABRICACION CIRCUIT BREAKER PANEL | H26: TALLERES XUQUER, SL | I26: TALLERES XUQUER, SL | J26: 1 | K26: 6240 | L26: 7488 | M26: EUR | N26: 1 | O26: 7488 | P26: CONGELADO | R26: SI | S26: SUBCONTRATO | T26: 1 | U26: SI | W26: S1072 | AA26: ok
A27: =IF(EXACT('BOM A320 FFS'!B37,obsoleta!D27),"OK","ERROR") -> ERROR | C27: COCKPIT | F27: VENTANAS COCKPIT SIM A320 SN04 | H27: TALLERES XUQUER, SL | I27: TALLERES XUQUER, SL | J27: 1 | K27: 312 | L27: 374.4 | M27: EUR | N27: 1 | O27: 374.4 | P27: CONGELADO | R27: SI | S27: SUBCONTRATO | T27: 1 | U27: SI | W27: S1072 | AA27: ok
A28: =IF(EXACT('BOM A320 FFS'!B39,obsoleta!D28),"OK","ERROR") -> ERROR | AA28: ok
A29: =IF(EXACT('BOM A320 FFS'!B40,obsoleta!D29),"OK","ERROR") -> ERROR | D29: Breakers | AA29: ok
A30: =IF(EXACT('BOM A320 FFS'!B41,obsoleta!D30),"OK","ERROR") -> ERROR | C30: CABINA | D30: 1124510125000 | F30: SWITCH MAGNETICO SPDT 28VDC 200MA C/FUS | G30: 9510-G111-P1F1-Z0R2B2 | H30: E.T.A. | I30: ELPO ELECTRIC, S.A. | J30: 290 | K30: 25.5 | L30: 30.6 | M30: EUR | N30: 1 | O30: 30.6 | P30: CONGELADO | Q30: 45453 | R30: NO | T30: 2 | W30: S1076 | X30: JA2587/1001 | Y30: 1 | Z30: rochoa | AA30: ok | AB30: 290
A31: =IF(EXACT('BOM A320 FFS'!B43,obsoleta!D31),"OK","ERROR") -> ERROR | C31: CABINA | D31: 1128990390300 | F31: ANILLO BLOQUEO OFF ROJO | G31: Y 307 005 01 | H31: E.T.A. | I31: ELPO ELECTRIC, S.A. | J31: 25 | K31: 4.58 | L31: 5.5 | M31: EUR | N31: 1 | O31: 5.5 | P31: CONGELADO | Q31: 45453 | R31: NO | T31: 2 | W31: S1076 | X31: JA2587/1001 | Y31: 1 | Z31: rochoa | AA31: ok | AB31: 25
A32: =IF(EXACT('BOM A320 FFS'!B44,obsoleta!D32),"OK","ERROR") -> ERROR | C32: CABINA | D32: 1124510126100 | F32: SWITCH MAGNETICO SPDT 28VDC 3A 200MA C/D | G32: 9510-G111-P1F1-Z0R2A2-3A | H32: E.T.A. | I32: ELPO ELECTRIC, S.A. | J32: 113 | K32: 25.5 | L32: 30.6 | M32: EUR | N32: 1 | O32: 30.6 | P32: CONGELADO | Q32: 45453 | R32: NO | T32: 2 | W32: S1076 | X32: JA2587/1001 | Y32: 1 | Z32: rochoa | AA32: ok | AB32: 113
A33: =IF(EXACT('BOM A320 FFS'!B46,obsoleta!D33),"OK","ERROR") -> ERROR | C33: CABINA | D33: 1124510125200 | F33: SWITCH MAGNETICO SPDT 28VDC 5A VERDE C/D | G33: 9510-G111-P1F1-Z0R2A2-5A | H33: E.T.A. | I33: ELPO ELECTRIC, S.A. | J33: 24 | K33: 25.5 | L33: 30.6 | M33: EUR | N33: 1 | O33: 30.6 | P33: CONGELADO | Q33: 45453 | R33: NO | T33: 2 | W33: S1076 | X33: JA2587/1001 | Y33: 1 | Z33: rochoa | AA33: ok | AB33: 24
A34: =IF(EXACT('BOM A320 FFS'!B47,obsoleta!D34),"OK","ERROR") -> ERROR | C34: CABINA | D34: 1124510125300 | F34: SWITCH MAGNETICO SPDT 28VDC 7A 200MA C/D | G34: 9510-G111-P1F1-Z0R2A2-7A | H34: E.T.A. | I34: ELPO ELECTRIC, S.A. | J34: 1 | K34: 25.5 | L34: 30.6 | M34: EUR | N34: 1 | O34: 30.6 | P34: CONGELADO | Q34: 45453 | R34: NO | T34: 2 | W34: S1076 | X34: JA2587/1001 | Y34: 1 | Z34: rochoa | AA34: ok | AB34: 5
A35: =IF(EXACT('BOM A320 FFS'!B48,obsoleta!D35),"OK","ERROR") -> ERROR | C35: CABINA | D35: 1124510125400 | F35: SWITCH MAGNETICO SPDT 28VDC 7.5A 200MA C | G35: 9510-G111-P1F1-Z0R2A2-7.5A | H35: E.T.A. | I35: ELPO ELECTRIC, S.A. | J35: 27 | K35: 25.5 | L35: 30.6 | M35: EUR | N35: 1 | O35: 30.6 | P35: CONGELADO | Q35: 45453 | R35: NO | T35: 2 | W35: S1076 | X35: JA2587/1001 | Y35: 1 | Z35: rochoa | AA35: ok | AB35: 27
A36: =IF(EXACT('BOM A320 FFS'!B50,obsoleta!D36),"OK","ERROR") -> ERROR | C36: CABINA | D36: 1124510125500 | F36: SWITCH MAGNETICO SPDT 28VDC 10A 200MA C/ | G36: 9510-G111-P1F1-Z0R2A2-10A | H36: E.T.A. | I36: ELPO ELECTRIC, S.A. | J36: 4 | K36: 25.5 | L36: 30.6 | M36: EUR | N36: 1 | O36: 30.6 | P36: CONGELADO | Q36: 45453 | R36: NO | T36: 2 | W36: S1076 | X36: JA2587/1001 | Y36: 1 | Z36: rochoa | AA36: ok | AB36: 5
A37: =IF(EXACT('BOM A320 FFS'!B51,obsoleta!D37),"OK","ERROR") -> ERROR | C37: CABINA | D37: 1124510125600 | F37: SWITCH MAGNETICO SPDT 28VDC 15A 200MA C/ | G37: 9510-G111-P1F1-Z0R2A2-15A | H37: E.T.A. | I37: ELPO ELECTRIC, S.A. | J37: 6 | K37: 25.5 | L37: 30.6 | M37: EUR | N37: 1 | O37: 30.6 | P37: CONGELADO | Q37: 45453 | R37: NO | T37: 2 | W37: S1076 | X37: JA2587/1001 | Y37: 1 | Z37: rochoa | AA37: ok | AB37: 6
A38: =IF(EXACT('BOM A320 FFS'!B52,obsoleta!D38),"OK","ERROR") -> ERROR | C38: CABINA | D38: 1124510125900 | F38: SWITCH MAGNETICO SPDT 28VDC 35A 200MA C/ | G38: 9510-G111-P1F1-Z0R2A2-35A | H38: E.T.A. | I38: ELPO ELECTRIC, S.A. | J38: 2 | K38: 25.5 | L38: 30.6 | M38: EUR | N38: 1 | O38: 30.6 | P38: CONGELADO | Q38: 45453 | R38: NO | T38: 2 | W38: S1076 | X38: JA2587/1001 | Y38: 1 | Z38: rochoa | AA38: ok | AB38: 5
A39: =IF(EXACT('BOM A320 FFS'!B53,obsoleta!D39),"OK","ERROR") -> ERROR | C39: CABINA | D39: 1124510126000 | F39: SWITCH MAGNETICO SPDT 28VDC 50A 200MA C/ | G39: 9510-G111-P1F1-Z0R2A2-50A | H39: E.T.A. | I39: ELPO ELECTRIC, S.A. | J39: 2 | K39: 25.5 | L39: 30.6 | M39: EUR | N39: 1 | O39: 30.6 | P39: CONGELADO | Q39: 45453 | R39: NO | T39: 2 | W39: S1076 | X39: JA2587/1001 | Y39: 1 | Z39: rochoa | AA39: ok | AB39: 5
A40: =IF(EXACT('BOM A320 FFS'!B54,obsoleta!D40),"OK","ERROR") -> ERROR | C40: CABINA | D40: 1124510125700 | F40: SWITCH MAGNETICO SPDT 28VDC 20A 200MA C/ | G40: 9510-G111-P1F1-Z0R2A2-20A | H40: E.T.A. | I40: ELPO ELECTRIC, S.A. | J40: 4 | K40: 25.5 | L40: 30.6 | M40: EUR | N40: 1 | O40: 30.6 | P40: CONGELADO | Q40: 45453 | R40: NO | T40: 2 | W40: S1076 | X40: JA2587/1001 | Y40: 1 | Z40: rochoa | AA40: ok | AB40: 5
...

Sheet SAP Equipos Compras
A1: Material | B1: Descripción material | C1: Fecha Sol. | D1: Nº Cesta / Sol | E1: Posición sol. | F1: Estado de la Firma | G1: Nº pedido | H1: Posición ped. | I1: Fecha Ped. | J1: Fe. Entrega | K1: Entrega final | L1: Ind.Borr/Bloq Ped | M1: Estado | N1: Ctd. Solicitada | O1: Ctd. pedido | P1: Ctd. Recepcionada | Q1: Ctd. por recepcionar | R1: Ctd. por inspeccionar | S1: Imp. unitario Ped. | T1: Imp.total pos Ped | U1: Moneda Ped. | V1: P/N fab. Ped | W1: Desc.Proveedor | X1: Elemento PEP | Y1: Almacen | Z1: Bloqueo Compras | AA1: Cant Base Ped. | AB1: Cant.base SP | AC1: Cantidad solicitada | AD1: Carácter longitud 1 | AE1: Centro | AF1: Cl. Pedido | AG1: Clase de operación | AH1: Clase de pedido | AI1: Clave de horizonte | AJ1: Creado por | AK1: CREADOR SP | AL1: Ctd. Aceptada | AM1: Ctd. Aceptada | AN1: Ctd. facturada | AO1: Ctd. por facturar | AP1: Ctd. por recepcionar | AQ1: Ctd. Rechazada | AR1: Desc. Fabricante en ped. | AS1: Desc. Mercado Organizativo (SolPed) | AT1: Descripción de la operación | AU1: Descripción fabricante en sp. | AV1: Dirección de Entrega | AW1: Documentacion | AX1: Entregas (de/a) | AY1: Fabricante en ped. | AZ1: Fabricante en sp | BA1: Fecha de documento | BB1: Fecha de entrada en compras | BC1: Fecha de entrega | BD1: Fecha de fin extrema | BE1: Fecha inicio extrema | BF1: Fecha Liberación | BG1: Fecha-apert. planif. | BH1: Grupo de artículos | BI1: Grupo de artículos Operación | BJ1: Imp.total pos SP | BK1: Imp.unit.SP | BL1: Ind.Borr/Bloq Sol | BM1: Indicador de borrado | BN1: Indicador liberación | BO1: Mercado Organizativo (SolPed) | BP1: Moneda | BQ1: Moneda | BR1: Moneda Ped | BS1: Moneda SP | BT1: Nombre completo | BU1: Número de material Padre | BV1: OP/Grafo | BW1: Orden previsional | BX1: P/N fab. sp. | BY1: Pedido Inmediato | BZ1: Plazo entrega prev. | CA1: Por calcular (cantidad) | CB1: Por calcular (valor) | CC1: Por facturar cantidad. | CD1: Proveedor | CE1: Status | CF1: Texto breve de material | CG1: Texto de cabecera | CH1: Tiempo espera normal | CI1: Tipo cambio | CJ1: Tipo Compra | CK1: Tipo de imputación | CL1: Tmpo.tratamiento EM | CM1: Total EM valor | CN1: Total entrada de mercancía(ctd) | CO1: Total facturas ctd. | CP1: Unid.tmp.nor.espera | CQ1: Unidad | CR1: Unidad | CS1: Unidad de medida | CT1: Unidad de medida | CU1: Unidad medida base | CV1: Unidad medida base | CW1: UnMedidaPrecioPedido | CX1: Valor aceptado | CY1: Valor ctd. aceptada | CZ1: Valor facturado | DA1: Valor por entregar | DB1: Valor por facturar | DC1: Valor por inspeccionar | DD1: Valor por recepcionar | DE1: Valor recepcionado | DF1: Solic. | DG1: Comprador
B2: HW OTP TOKEN 1 YEAR (WITH PROOFING) | C2: 44796 | D2: 1101528754 | E2: 1 | H2: 0 | N2: 1 | O2: 0 | P2: 0 | Q2: 0 | R2: 0 | S2: 0 | T2: 0 | X2: 7218|S22B04_GPR05 | AA2: 0 | AB2: 1 | AE2: 6000 | AJ2: SRM2ERP | AK2: SRM2ERP | AL2: 0 | AN2: 0 | AO2: 0 | AQ2: 0 | AS2: Simulacion | AV2: Calle Mar Egeo,428830San Fernando de Henares | AW2: '@FM@ | AX2: 44796 | BB2: 44796 | BF2: 44796 | BH2: 432411 | BJ2: 105 | BK2: 105 | BO2: 20 | BS2: USD | BT2: María Isabel Recio Gutiérrez | BZ2: 0 | CA2: 0 | CB2: 0 | CH2: 0 | CK2: P | CL2: 0 | CM2: 0.00 | CX2: 0 | CZ2: 0 | DA2: 0.00 | DB2: 0 | DC2: 0 | DD2: 0 | DE2: 0 | DF2: MRECIO | DG2: Sanchez Graciano, Antonio
A3: 1390701500800 | B3: MCDU B737-800 FANS S/OF | C3: 44796 | D3: 1101528790 | E3: 1 | G3: 4600003331 | H3: 10 | I3: 44802 | J3: 45044 | M3: Liberado | N3: 2 | O3: 2 | P3: 0 | Q3: 2 | R3: 0 | S3: 17575 | T3: 35150 | U3: USD | V3: 631-922425-001 | W3: SYMBOLIC DISPLAYS, INC | X3: 7218|S22B04_S1041 | Y3: 8990 | AA3: 1 | AB3: 1 | AE3: 8000 | AF3: Ped. antici. hitos | AH3: ZANT | AJ3: 152028 | AK3: SRM2ERP | AL3: 0 | AN3: 0 | AO3: 2 | AQ3: 0 | AR3: SDI | AS3: Simulacion | AV3: Avenida de la Veguilla,419171Cabanillas del Campo | AW3: '@FM@ | AX3: 44865 | AY3: 9002524 | BB3: 44802 | BC3: 45044 | BF3: 44802 | BH3: 322020 | BJ3: 35150 | BK3: 17575 | BN3: 3 | BO3: 20 | BP3: USD | BR3: USD | BS3: USD | BT3: Arsenio Jiménez Pérez | BZ3: 40 | CA3: 2 | CB3: 35150 | CD3: 1051015 | CH3: 0 | CI3: 0,98795 | CK3: Q | CL3: 8 | CM3: 0.00 | CQ3: UN | CR3: UN | CS3: UN | CT3: UN | CU3: UN | CV3: UN | CW3: UN | CX3: 0 | CZ3: 0 | DA3: 35150.00 | DB3: 35150 | DC3: 0 | DD3: 35150 | DE3: 0 | DF3: AJIMENEZP | DG3: Fernández Carrascal, José Abel
A4: 9999000322010 | B4: N.R. PANELES SIMULADORES | C4: 44796 | D4: 1101528790 | E4: 3 | G4: 4600003331 | H4: 20 | I4: 44802 | J4: 45044 | M4: Liberado | N4: 1 | O4: 1 | P4: 0 | Q4: 1 | R4: 0 | S4: 2700 | T4: 2700 | U4: USD | W4: SYMBOLIC DISPLAYS, INC | X4: 7218|S22B04_S1041 | AA4: 1 | AB4: 1 | AE4: 8000 | AF4: Ped. antici. hitos | AH4: ZANT | AJ4: 152028 | AK4: SRM2ERP | AL4: 0 | AN4: 0 | AO4: 1 | AQ4: 0 | AS4: Simulacion | AV4: Calle Mar Egeo,428830San Fernando de Henares | AW4: '@FM@ | AX4: 44865 | BB4: 44802 | BC4: 45044 | BF4: 44802 | BH4: 322010 | BJ4: 2700 | BK4: 2700 | BN4: 3 | BO4: 20 | BP4: USD | BR4: USD | BS4: USD | BT4: Arsenio Jiménez Pérez | BZ4: 195 | CA4: 1 | CB4: 2700 | CD4: 1051015 | CH4: 0 | CI4: 0,98795 | CK4: P | CL4: 8 | CM4: 0.00 | CQ4: UN | CR4: UN | CS4: UN | CT4: UN | CU4: UN | CV4: UN | CW4: UN | CX4: 0 | CZ4: 0 | DA4: 2700.00 | DB4: 2700 | DC4: 0 | DD4: 2700 | DE4: 0 | DF4: AJIMENEZP | DG4: Fernández Carrascal, José Abel
A5: 1390701500100 | B5: B737-800 DISPLAY UNIT 631-909698-901 | C5: 44796 | D5: 1101528790 | E5: 4 | G5: 4600003331 | H5: 30 | I5: 44802 | J5: 44969 | M5: Liberado | N5: 5 | O5: 5 | P5: 0 | Q5: 5 | R5: 0 | S5: 13310 | T5: 66550 | U5: USD | V5: 631-909698-901 | W5: SYMBOLIC DISPLAYS, INC | X5: 7218|S22B04_S1041 | Y5: 8990 | AA5: 1 | AB5: 1 | AE5: 8000 | AF5: Ped. antici. hitos | AH5: ZANT | AJ5: 152028 | AK5: SRM2ERP | AL5: 0 | AN5: 0 | AO5: 5 | AQ5: 0 | AR5: SDI | AS5: Simulacion | AV5: Avenida de la Veguilla,419171Cabanillas del Campo | AW5: '@FM@ | AX5: 44865 | AY5: 9002524 | BB5: 44802 | BC5: 44969 | BF5: 44827 | BH5: 322020 | BJ5: 66550 | BK5: 13310 | BN5: 3 | BO5: 20 | BP5: USD | BR5: USD | BS5: USD | BT5: Arsenio Jiménez Pérez | BZ5: 4 | CA5: 5 | CB5: 66550 | CD5: 1051015 | CH5: 0 | CI5: 0,98795 | CK5: Q | CL5: 8 | CM5: 0.00 | CQ5: UN | CR5: UN | CS5: UN | CT5: UN | CU5: UN | CV5: UN | CW5: UN | CX5: 0 | CZ5: 0 | DA5: 66550.00 | DB5: 66550 | DC5: 0 | DD5: 66550 | DE5: 0 | DF5: AJIMENEZP | DG5: Fernández Carrascal, José Abel
A6: 1309000611900 | B6: CTL PANEL WEATHER RADAR | C6: 44754 | D6: 1101517813 | E6: 1 | G6: 4200484030 | H6: 10 | I6: 44761 | J6: 44819 | M6: Liberado | N6: 1 | O6: 1 | P6: 1 | Q6: 0 | R6: 1 | S6: 15329.57 | T6: 15329.57 | U6: EUR | V6: 622-5129-802 | W6: AEROFALCON S.L. | X6: 7218|S22B04_S1076 | Y6: 8990 | AA6: 1 | AB6: 1 | AE6: 8000 | AF6: Pedido de materiales | AH6: ZNB | AJ6: 947726 | AK6: SRM2ERP | AL6: 0 | AN6: 0 | AO6: 1 | AQ6: 0 | AR6: ROCKWELL-COLLINS | AS6: Simulacion | AV6: El Rayo (Polig Indust La Quinta,719171Cabanillas del Campo | AW6: '@FM@ | AX6: 44826 | AY6: 9000328 | BB6: 44754 | BC6: 44819 | BF6: 44777 | BH6: 425027 | BJ6: 15329.57 | BK6: 15329.57 | BN6: 3 | BO6: 20 | BP6: EUR | BR6: EUR | BS6: EUR | BT6: María Ángeles Coello Roma | BZ6: 15 | CA6: 1 | CB6: 15329.57 | CD6: 1205312 | CH6: 0 | CI6: 1,00000 | CK6: Q | CL6: 8 | CM6: 15329.57 | CQ6: UN | CR6: UN | CS6: UN | CT6: UN | CU6: UN | CV6: UN | CW6: UN | CX6: 0 | CZ6: 0 | DA6: 0.00 | DB6: 15329.57 | DC6: 15329.57 | DD6: 0 | DE6: 15329.57 | DF6: ACOELLO | DG6: Ortiz Diaz, Carolina
A7: 1390703220100 | B7: CABIN PRESS PANEL SIM REPLI 814392-2-002 | C7: 44753 | D7: 1101517234 | E7: 1 | G7: 4200483039 | H7: 10 | I7: 44755 | J7: 44959 | M7: Liberado | N7: 1 | O7: 1 | P7: 0 | Q7: 1 | R7: 0 | S7: 21270 | T7: 21270 | U7: USD | V7: 10-7829 | W7: SIMTEK, INC | X7: 7218|S22B04_S1076 | Y7: 8990 | AA7: 1 | AB7: 1 | AE7: 8000 | AF7: Pedido de materiales | AH7: ZNB | AJ7: 152028 | AK7: SRM2ERP | AL7: 0 | AN7: 0 | AO7: 1 | AQ7: 0 | AR7: SIMTEK | AS7: Simulacion | AV7: El Rayo (Polig Indust La Quinta,719171Cabanillas del Campo | AW7: '@FM@ | AX7: 44826 | AY7: 9008133 | BC7: 44959 | BH7: 322010 | BJ7: 41300 | BK7: 41300 | BN7: 3 | BO7: 20 | BP7: USD | BR7: USD | BS7: USD | BT7: María Ángeles Coello Roma | BZ7: 142 | CA7: 1 | CB7: 21270 | CD7: 1047453 | CH7: 0 | CI7: 0,96274 | CK7: Q | CL7: 8 | CM7: 0.00 | CQ7: UN | CR7: UN | CS7: UN | CT7: UN | CU7: UN | CV7: UN | CW7: UN | CX7: 0 | CZ7: 0 | DA7: 21270.00 | DB7: 21270 | DC7: 0 | DD7: 21270 | DE7: 0 | DF7: ACOELLO | DG7: Ramos Torreadrado, Carolina
A8: 1390703021100 | B8: RUDDER TRIM POS IND SIM PN: 10166N01N00 | C8: 44753 | D8: 1101517234 | E8: 2 | G8: 4200483039 | H8: 20 | I8: 44755 | J8: 44959 | M8: Liberado | N8: 1 | O8: 1 | P8: 0 | Q8: 1 | R8: 0 | S8: 5330 | T8: 5330 | U8: USD | V8: 10-7774 | W8: SIMTEK, INC | X8: 7218|S22B04_S1076 | Y8: 8990 | AA8: 1 | AB8: 1 | AE8: 8000 | AF8: Pedido de materiales | AH8: ZNB | AJ8: 152028 | AK8: SRM2ERP | AL8: 0 | AN8: 0 | AO8: 1 | AQ8: 0 | AR8: SIMTEK | AS8: Simulacion | AV8: El Rayo (Polig Indust La Quinta,719171Cabanillas del Campo | AW8: '@FM@ | AX8: 44826 | AY8: 9008133 | BB8: 44753 | BC8: 44959 | BF8: 44777 | BH8: 322010 | BJ8: 9980 | BK8: 9980 | BN8: 3 | BO8: 20 | BP8: USD | BR8: USD | BS8: USD | BT8: María Ángeles Coello Roma | BZ8: 15 | CA8: 1 | CB8: 5330 | CD8: 1047453 | CH8: 0 | CI8: 0,96274 | CK8: Q | CL8: 8 | CM8: 0.00 | CQ8: UN | CR8: UN | CS8: UN | CT8: UN | CU8: UN | CV8: UN | CW8: UN | CX8: 0 | CZ8: 0 | DA8: 5330.00 | DB8: 5330 | DC8: 0 | DD8: 5330 | DE8: 0 | DF8: ACOELLO | DG8: Ramos Torreadrado, Carolina
A9: 1390703021000 | B9: ANNUNCIATOR PANEL SIM PN: D434-56-001 | C9: 44753 | D9: 1101517234 | E9: 3 | G9: 4200483039 | H9: 30 | I9: 44755 | J9: 44959 | M9: Liberado | N9: 2 | O9: 2 | P9: 0 | Q9: 2 | R9: 0 | S9: 3780 | T9: 7560 | U9: USD | V9: 10-7773 | W9: SIMTEK, INC | X9: 7218|S22B04_S1076 | Y9: 8990 | AA9: 1 | AB9: 1 | AE9: 8000 | AF9: Pedido de materiales | AH9: ZNB | AJ9: 152028 | AK9: SRM2ERP | AL9: 0 | AN9: 0 | AO9: 2 | AQ9: 0 | AR9: SIMTEK | AS9: Simulacion | AV9: El Rayo (Polig Indust La Quinta,719171Cabanillas del Campo | AW9: '@FM@ | AX9: 44826 | AY9: 9008133 | BC9: 44959 | BH9: 322010 | BJ9: 20430 | BK9: 10215 | BN9: 3 | BO9: 20 | BP9: USD | BR9: USD | BS9: USD | BT9: María Ángeles Coello Roma | BZ9: 15 | CA9: 2 | CB9: 7560 | CD9: 1047453 | CH9: 0 | CI9: 0,96274 | CK9: Q | CL9: 8 | CM9: 0.00 | CQ9: UN | CR9: UN | CS9: UN | CT9: UN | CU9: UN | CV9: UN | CW9: UN | CX9: 0 | CZ9: 0 | DA9: 7560.00 | DB9: 7560 | DC9: 0 | DD9: 7560 | DE9: 0 | DF9: ACOELLO | DG9: Ramos Torreadrado, Carolina
A10: 1390703020900 | B10: COMPASS SIM REPLICA PN: C5L | C10: 44753 | D10: 1101517234 | E10: 4 | G10: 4200483039 | H10: 40 | I10: 44755 | J10: 44959 | M10: Liberado | N10: 1 | O10: 1 | P10: 0 | Q10: 1 | R10: 0 | S10: 3695 | T10: 3695 | U10: USD | V10: 10-7772 | W10: SIMTEK, INC | X10: 7218|S22B04_S1076 | Y10: 8990 | AA10: 1 | AB10: 1 | AE10: 8000 | AF10: Pedido de materiales | AH10: ZNB | AJ10: SRM2ERP | AK10: SRM2ERP | AL10: 0 | AN10: 0 | AO10: 1 | AQ10: 0 | AR10: SIMTEK | AS10: Simulacion | AV10: El Rayo (Polig Indust La Quinta,719171Cabanillas del Campo | AW10: '@FM@ | AX10: 44826 | AY10: 9008133 | BB10: 44753 | BC10: 44959 | BF10: 44777 | BH10: 322010 | BJ10: 7180 | BK10: 7180 | BN10: 3 | BO10: 20 | BP10: USD | BR10: USD | BS10: USD | BT10: María Ángeles Coello Roma | BZ10: 15 | CA10: 1 | CB10: 3695 | CD10: 1047453 | CH10: 0 | CI10: 0,96274 | CK10: Q | CL10: 8 | CM10: 0.00 | CQ10: UN | CR10: UN | CS10: UN | CT10: UN | CU10: UN | CV10: UN | CW10: UN | CX10: 0 | CZ10: 0 | DA10: 3695.00 | DB10: 3695 | DC10: 0 | DD10: 3695 | DE10: 0 | DF10: ACOELLO | DG10: Ramos Torreadrado, Carolina
A11: 1390703020800 | B11: BRAKE PRESSURE IND SIM REPL PN: 163LCP80 | C11: 44753 | D11: 1101517234 | E11: 5 | G11: 4200483039 | H11: 50 | I11: 44755 | J11: 44959 | M11: Liberado | N11: 1 | O11: 1 | P11: 0 | Q11: 1 | R11: 0 | S11: 2755 | T11: 2755 | U11: USD | V11: 10-7771 | W11: SIMTEK, INC | X11: 7218|S22B04_S1076 | Y11: 8990 | AA11: 1 | AB11: 1 | AE11: 8000 | AF11: Pedido de materiales | AH11: ZNB | AJ11: 152028 | AK11: SRM2ERP | AL11: 0 | AN11: 0 | AO11: 1 | AQ11: 0 | AR11: SIMTEK | AS11: Simulacion | AV11: El Rayo (Polig Indust La Quinta,719171Cabanillas del Campo | AW11: '@FM@ | AX11: 44826 | AY11: 9008133 | BB11: 44753 | BC11: 44959 | BF11: 44777 | BH11: 322010 | BJ11: 5350 | BK11: 5350 | BN11: 3 | BO11: 20 | BP11: USD | BR11: USD | BS11: USD | BT11: María Ángeles Coello Roma | BZ11: 15 | CA11: 1 | CB11: 2755 | CD11: 1047453 | CH11: 0 | CI11: 0,96274 | CK11: Q | CL11: 8 | CM11: 0.00 | CQ11: UN | CR11: UN | CS11: UN | CT11: UN | CU11: UN | CV11: UN | CW11: UN | CX11: 0 | CZ11: 0 | DA11: 2755.00 | DB11: 2755 | DC11: 0 | DD11: 2755 | DE11: 0 | DF11: ACOELLO | DG11: Ramos Torreadrado, Carolina
A12: 1390703020700 | B12: FLAP POSITION IND SIM REPL PN: 2061-15-1 | C12: 44753 | D12: 1101517234 | E12: 6 | G12: 4200483039 | H12: 60 | I12: 44755 | J12: 44959 | M12: Liberado | N12: 1 | O12: 1 | P12: 0 | Q12: 1 | R12: 0 | S12: 4175 | T12: 4175 | U12: USD | V12: 10-7770 | W12: SIMTEK, INC | X12: 7218|S22B04_S1076 | Y12: 8990 | AA12: 1 | AB12: 1 | AE12: 8000 | AF12: Pedido de materiales | AH12: ZNB | AJ12: 152028 | AK12: SRM2ERP | AL12: 0 | AN12: 0 | AO12: 1 | AQ12: 0 | AR12: SIMTEK | AS12: Simulacion | AV12: El Rayo (Polig Indust La Quinta,719171Cabanillas del Campo | AW12: '@FM@ | AX12: 44826 | AY12: 9008133 | BB12: 44753 | BC12: 44959 | BF12: 44777 | BH12: 322010 | BJ12: 8110 | BK12: 8110 | BN12: 3 | BO12: 20 | BP12: USD | BR12: USD | BS12: USD | BT12: María Ángeles Coello Roma | BZ12: 15 | CA12: 1 | CB12: 4175 | CD12: 1047453 | CH12: 0 | CI12: 0,96274 | CK12: Q | CL12: 8 | CM12: 0.00 | CQ12: UN | CR12: UN | CS12: UN | CT12: UN | CU12: UN | CV12: UN | CW12: UN | CX12: 0 | CZ12: 0 | DA12: 4175.00 | DB12: 4175 | DC12: 0 | DD12: 4175 | DE12: 0 | DF12: ACOELLO | DG12: Ramos Torreadrado, Carolina
A13: 1390703020600 | B13: OXYGEN PRESSURE IND SIM REPLI PN: 182936 | C13: 44753 | D13: 1101517234 | E13: 7 | G13: 4200483039 | H13: 70 | I13: 44755 | J13: 44959 | M13: Liberado | N13: 1 | O13: 1 | P13: 0 | Q13: 1 | R13: 0 | S13: 2490 | T13: 2490 | U13: USD | V13: 10-7769 | W13: SIMTEK, INC | X13: 7218|S22B04_S1076 | Y13: 8990 | AA13: 1 | AB13: 1 | AE13: 8000 | AF13: Pedido de materiales | AH13: ZNB | AJ13: SRM2ERP | AK13: SRM2ERP | AL13: 0 | AN13: 0 | AO13: 1 | AQ13: 0 | AR13: SIMTEK | AS13: Simulacion | AV13: El Rayo (Polig Indust La Quinta,719171Cabanillas del Campo | AW13: '@FM@ | AX13: 44826 | AY13: 9008133 | BB13: 44753 | BC13: 44959 | BF13: 44777 | BH13: 322010 | BJ13: 3830 | BK13: 3830 | BN13: 3 | BO13: 20 | BP13: USD | BR13: USD | BS13: USD | BT13: María Ángeles Coello Roma | BZ13: 15 | CA13: 1 | CB13: 2490 | CD13: 1047453 | CH13: 0 | CI13: 0,96274 | CK13: Q | CL13: 8 | CM13: 0.00 | CQ13: UN | CR13: UN | CS13: UN | CT13: UN | CU13: UN | CV13: UN | CW13: UN | CX13: 0 | CZ13: 0 | DA13: 2490.00 | DB13: 2490 | DC13: 0 | DD13: 2490 | DE13: 0 | DF13: ACOELLO | DG13: Ramos Torreadrado, Carolina
A14: 1390703020500 | B14: DUCT PRESSURE IND SIM REPLI PN: SEDLOC9C | C14: 44753 | D14: 1101517234 | E14: 8 | G14: 4200483039 | H14: 80 | I14: 44755 | J14: 44959 | M14: Liberado | N14: 1 | O14: 1 | P14: 0 | Q14: 1 | R14: 0 | S14: 4175 | T14: 4175 | U14: USD | V14: 10-7768 | W14: SIMTEK, INC | X14: 7218|S22B04_S1076 | Y14: 8990 | AA14: 1 | AB14: 1 | AE14: 8000 | AF14: Pedido de materiales | AH14: ZNB | AJ14: SRM2ERP | AK14: SRM2ERP | AL14: 0 | AN14: 0 | AO14: 1 | AQ14: 0 | AR14: SIMTEK | AS14: Simulacion | AV14: El Rayo (Polig Indust La Quinta,719171Cabanillas del Campo | AW14: '@FM@ | AX14: 44826 | AY14: 9008133 | BB14: 44753 | BC14: 44959 | BF14: 44777 | BH14: 322010 | BJ14: 8110 | BK14: 8110 | BN14: 3 | BO14: 20 | BP14: USD | BR14: USD | BS14: USD | BT14: María Ángeles Coello Roma | BZ14: 15 | CA14: 1 | CB14: 4175 | CD14: 1047453 | CH14: 0 | CI14: 0,96274 | CK14: Q | CL14: 8 | CM14: 0.00 | CQ14: UN | CR14: UN | CS14: UN | CT14: UN | CU14: UN | CV14: UN | CW14: UN | CX14: 0 | CZ14: 0 | DA14: 4175.00 | DB14: 4175 | DC14: 0 | DD14: 4175 | DE14: 0 | DF14: ACOELLO | DG14: Ramos Torreadrado, Carolina
A15: 1390703020400 | B15: CABIN TEMP IND SIM REPLICA PN: 162BL903 | C15: 44753 | D15: 1101517234 | E15: 9 | G15: 4200483039 | H15: 90 | I15: 44755 | J15: 44959 | M15: Liberado | N15: 1 | O15: 1 | P15: 0 | Q15: 1 | R15: 0 | S15: 2565 | T15: 2565 | U15: USD | V15: 10-7767 | W15: SIMTEK, INC | X15: 7218|S22B04_S1076 | Y15: 8990 | AA15: 1 | AB15: 1 | AE15: 8000 | AF15: Pedido de materiales | AH15: ZNB | AK15: SRM2ERP | AL15: 0 | AN15: 0 | AO15: 1 | AQ15: 0 | AR15: SIMTEK | AS15: Simulacion | AV15: El Rayo (Polig Indust La Quinta,719171Cabanillas del Campo | AW15: '@FM@ | AX15: 44826 | AY15: 9008133 | BC15: 44959 | BH15: 322010 | BJ15: 3830 | BK15: 3830 | BN15: 3 | BO15: 20 | BP15: USD | BR15: USD | BS15: USD | BT15: María Ángeles Coello Roma | BZ15: 15 | CA15: 1 | CB15: 2565 | CD15: 1047453 | CH15: 0 | CI15: 0,96274 | CK15: Q | CL15: 8 | CM15: 0.00 | CQ15: UN | CR15: UN | CS15: UN | CT15: UN | CU15: UN | CV15: UN | CW15: UN | CX15: 0 | CZ15: 0 | DA15: 2565.00 | DB15: 2565 | DC15: 0 | DD15: 2565 | DE15: 0 | DF15: ACOELLO | DG15: Ramos Torreadrado, Carolina
A16: 1390703020300 | B16: CABIN VERTICA SPEED IND SIM PN: WL501RC1 | C16: 44753 | D16: 1101517234 | E16: 10 | G16: 4200483039 | H16: 100 | I16: 44755 | J16: 44959 | M16: Liberado | N16: 1 | O16: 1 | P16: 0 | Q16: 1 | R16: 0 | S16: 2585 | T16: 2585 | U16: USD | V16: 10-7766 | W16: SIMTEK, INC | X16: 7218|S22B04_S1076 | Y16: 8990 | AA16: 1 | AB16: 1 | AE16: 8000 | AF16: Pedido de materiales | AH16: ZNB | AJ16: 152028 | AK16: SRM2ERP | AL16: 0 | AN16: 0 | AO16: 1 | AQ16: 0 | AR16: SIMTEK | AS16: Simulacion | AV16: El Rayo (Polig Indust La Quinta,719171Cabanillas del Campo | AW16: '@FM@ | AX16: 44826 | AY16: 9008133 | BB16: 44753 | BC16: 44959 | BF16: 44777 | BH16: 322010 | BJ16: 5020 | BK16: 5020 | BN16: 3 | BO16: 20 | BP16: USD | BR16: USD | BS16: USD | BT16: María Ángeles Coello Roma | BZ16: 15 | CA16: 1 | CB16: 2585 | CD16: 1047453 | CH16: 0 | CI16: 0,96274 | CK16: Q | CL16: 8 | CM16: 0.00 | CQ16: UN | CR16: UN | CS16: UN | CT16: UN | CU16: UN | CV16: UN | CW16: UN | CX16: 0 | CZ16: 0 | DA16: 2585.00 | DB16: 2585 | DC16: 0 | DD16: 2585 | DE16: 0 | DF16: ACOELLO | DG16: Ramos Torreadrado, Carolina
A17: 1390703020200 | B17: CAB ALT/DIFF PRES IND SIM PN: AW2835AB06 | C17: 44753 | D17: 1101517234 | E17: 11 | G17: 4200483039 | H17: 110 | I17: 44755 | J17: 44959 | M17: Liberado | N17: 1 | O17: 1 | P17: 0 | Q17: 1 | R17: 0 | S17: 4175 | T17: 4175 | U17: USD | V17: 10-7765 | W17: SIMTEK, INC | X17: 7218|S22B04_S1076 | Y17: 8990 | AA17: 1 | AB17: 1 | AE17: 8000 | AF17: Pedido de materiales | AH17: ZNB | AJ17: SRM2ERP | AK17: SRM2ERP | AL17: 0 | AN17: 0 | AO17: 1 | AQ17: 0 | AR17: SIMTEK | AS17: Simulacion | AV17: El Rayo (Polig Indust La Quinta,719171Cabanillas del Campo | AW17: '@FM@ | AX17: 44826 | AY17: 9008133 | BB17: 44753 | BC17: 44959 | BF17: 44777 | BH17: 322010 | BJ17: 8110 | BK17: 8110 | BN17: 3 | BO17: 20 | BP17: USD | BR17: USD | BS17: USD | BT17: María Ángeles Coello Roma | BZ17: 15 | CA17: 1 | CB17: 4175 | CD17: 1047453 | CH17: 0 | CI17: 0,96274 | CK17: Q | CL17: 8 | CM17: 0.00 | CQ17: UN | CR17: UN | CS17: UN | CT17: UN | CU17: UN | CV17: UN | CW17: UN | CX17: 0 | CZ17: 0 | DA17: 4175.00 | DB17: 4175 | DC17: 0 | DD17: 4175 | DE17: 0 | DF17: ACOELLO | DG17: Ramos Torreadrado, Carolina
A18: 1390703020100 | B18: EGT APU SIM REPLICA PN: 152LMA23 | C18: 44753 | D18: 1101517234 | E18: 12 | G18: 4200483039 | H18: 120 | I18: 44755 | J18: 44959 | M18: Liberado | N18: 1 | O18: 1 | P18: 0 | Q18: 1 | R18: 0 | S18: 2565 | T18: 2565 | U18: USD | V18: 10-7764 | W18: SIMTEK, INC | X18: 7218|S22B04_S1076 | Y18: 8990 | AA18: 1 | AB18: 1 | AE18: 8000 | AF18: Pedido de materiales | AH18: ZNB | AJ18: SRM2ERP | AK18: SRM2ERP | AL18: 0 | AN18: 0 | AO18: 1 | AQ18: 0 | AR18: SIMTEK | AS18: Simulacion | AV18: El Rayo (Polig Indust La Quinta,719171Cabanillas del Campo | AW18: '@FM@ | AX18: 44826 | AY18: 9008133 | BB18: 44753 | BC18: 44959 | BF18: 44777 | BH18: 322020 | BJ18: 3980 | BK18: 3980 | BN18: 3 | BO18: 20 | BP18: USD | BR18: USD | BS18: USD | BT18: María Ángeles Coello Roma | BZ18: 15 | CA18: 1 | CB18: 2565 | CD18: 1047453 | CH18: 0 | CI18: 0,96274 | CK18: Q | CL18: 8 | CM18: 0.00 | CQ18: UN | CR18: UN | CS18: UN | CT18: UN | CU18: UN | CV18: UN | CW18: UN | CX18: 0 | CZ18: 0 | DA18: 2565.00 | DB18: 2565 | DC18: 0 | DD18: 2565 | DE18: 0 | DF18: ACOELLO | DG18: Ramos Torreadrado, Carolina
A19: 1390703020000 | B19: FUEL TEMP IND SIM REPLICA PN:162BL801 | C19: 44753 | D19: 1101517234 | E19: 13 | G19: 4200483039 | H19: 130 | I19: 44755 | J19: 44959 | M19: Liberado | N19: 1 | O19: 1 | P19: 0 | Q19: 1 | R19: 0 | S19: 2565 | T19: 2565 | U19: USD | V19: 10-7763 | W19: SIMTEK, INC | X19: 7218|S22B04_S1076 | Y19: 8990 | AA19: 1 | AB19: 1 | AE19: 8000 | AF19: Pedido de materiales | AH19: ZNB | AJ19: 152028 | AK19: SRM2ERP | AL19: 0 | AN19: 0 | AO19: 1 | AQ19: 0 | AR19: SIMTEK | AS19: Simulacion | AV19: El Rayo (Polig Indust La Quinta,719171Cabanillas del Campo | AW19: '@FM@ | AX19: 44826 | AY19: 9008133 | BC19: 44959 | BH19: 322010 | BJ19: 3980 | BK19: 3980 | BN19: 3 | BO19: 20 | BP19: USD | BR19: USD | BS19: USD | BT19: María Ángeles Coello Roma | BZ19: 15 | CA19: 1 | CB19: 2565 | CD19: 1047453 | CH19: 0 | CI19: 0,96274 | CK19: Q | CL19: 8 | CM19: 0.00 | CQ19: UN | CR19: UN | CS19: UN | CT19: UN | CU19: UN | CV19: UN | CW19: UN | CX19: 0 | CZ19: 0 | DA19: 2565.00 | DB19: 2565 | DC19: 0 | DD19: 2565 | DE19: 0 | DF19: ACOELLO | DG19: Ramos Torreadrado, Carolina
A20: 1390703021300 | B20: AIR VALVE POSITION | C20: 44753 | D20: 1101517234 | E20: 14 | G20: 4200483039 | H20: 140 | I20: 44755 | J20: 44959 | M20: Liberado | N20: 2 | O20: 2 | P20: 0 | Q20: 2 | R20: 0 | S20: 1875 | T20: 3750 | U20: USD | V20: 51-0230-01 | W20: SIMTEK, INC | X20: 7218|S22B04_S1076 | Y20: 8990 | AA20: 1 | AB20: 1 | AE20: 8000 | AF20: Pedido de materiales | AH20: ZNB | AJ20: 152028 | AK20: SRM2ERP | AL20: 0 | AN20: 0 | AO20: 2 | AQ20: 0 | AR20: SIMTEK | AS20: Simulacion | AV20: El Rayo (Polig Indust La Quinta,719171Cabanillas del Campo | AW20: '@FM@ | AX20: 44826 | AY20: 9008133 | BC20: 44959 | BH20: 322020 | BJ20: 2510 | BK20: 1255 | BN20: 3 | BO20: 20 | BP20: USD | BR20: USD | BS20: USD | BT20: María Ángeles Coello Roma | BZ20: 204 | CA20: 2 | CB20: 3750 | CD20: 1047453 | CH20: 0 | CI20: 0,96274 | CK20: Q | CL20: 8 | CM20: 0.00 | CQ20: UN | CR20: UN | CS20: UN | CT20: UN | CU20: UN | CV20: UN | CW20: UN | CX20: 0 | CZ20: 0 | DA20: 3750.00 | DB20: 3750 | DC20: 0 | DD20: 3750 | DE20: 0 | DF20: ACOELLO | DG20: Ramos Torreadrado, Carolina
A21: 1390702740000 | B21: CLOCK | C21: 44750 | D21: 1101516960 | E21: 1 | G21: 4200482994 | H21: 10 | I21: 44755 | J21: 44772 | M21: Generado documento | N21: 2 | O21: 2 | P21: 0 | Q21: 2 | R21: 0 | S21: 8659 | T21: 17318 | U21: USD | V21: 9010-1-3 | W21: THE BOEING COMPANY | X21: 7218|S22B04_S1076 | Y21: 8990 | AA21: 1 | AB21: 1 | AE21: 8000 | AF21: Pedido de materiales | AH21: ZNB | AJ21: SRM2ERP | AK21: SRM2ERP | AL21: 0 | AN21: 0 | AO21: 2 | AQ21: 0 | AR21: AVTECH CORPORATION | AS21: Simulacion | AV21: El Rayo (Polig Indust La Quinta,719171Cabanillas del Campo | AW21: '@FM@ | AX21: 44820 | AY21: 9010466 | BB21: 44753 | BC21: 44772 | BF21: 44760 | BH21: 322010 | BJ21: 17318 | BK21: 8659 | BN21: X | BO21: 20 | BP21: USD | BR21: USD | BS21: USD | BT21: María Ángeles Coello Roma | BZ21: 28 | CA21: 2 | CB21: 17318 | CD21: 1046021 | CH21: 0 | CI21: 0,96274 | CK21: Q | CL21: 8 | CM21: 0.00 | CQ21: UN | CR21: UN | CS21: UN | CT21: UN | CU21: UN | CV21: UN | CW21: UN | CX21: 0 | CZ21: 0 | DA21: 17318.00 | DB21: 17318 | DC21: 0 | DD21: 17318 | DE21: 0 | DF21: ACOELLO | DG21: Ramos Torreadrado, Carolina
A22: 1390702720000 | B22: REMOTE LIGHT SENSOR | C22: 44750 | D22: 1101516960 | E22: 2 | G22: 4200482994 | H22: 20 | I22: 44755 | J22: 45019 | M22: Generado documento | N22: 2 | O22: 2 | P22: 0 | Q22: 2 | R22: 0 | S22: 10970 | T22: 21940 | U22: USD | V22: 4082740-901 | W22: THE BOEING COMPANY | X22: 7218|S22B04_S1076 | Y22: 8990 | AA22: 1 | AB22: 1 | AE22: 8000 | AF22: Pedido de materiales | AH22: ZNB | AK22: SRM2ERP | AL22: 0 | AN22: 0 | AO22: 2 | AQ22: 0 | AR22: HONEYWELL INC | AS22: Simulacion | AV22: El Rayo (Polig Indust La Quinta,719171Cabanillas del Campo | AW22: '@FM@ | AX22: 44820 | AY22: 9003555 | BC22: 45019 | BH22: 322020 | BJ22: 21940 | BK22: 10970 | BN22: X | BO22: 20 | BP22: USD | BR22: USD | BS22: USD | BT22: María Ángeles Coello Roma | BZ22: 25 | CA22: 2 | CB22: 21940 | CD22: 1046021 | CH22: 0 | CI22: 0,96274 | CK22: Q | CL22: 8 | CM22: 0.00 | CQ22: UN | CR22: UN | CS22: UN | CT22: UN | CU22: UN | CV22: UN | CW22: UN | CX22: 0 | CZ22: 0 | DA22: 21940.00 | DB22: 21940 | DC22: 0 | DD22: 21940 | DE22: 0 | DF22: ACOELLO | DG22: Ramos Torreadrado, Carolina
A23: 1390705171100 | B23: PANEL ASSY-MAP/CHART LT CONT P23-1 | C23: 44750 | D23: 1101516960 | E23: 3 | G23: 4200482994 | H23: 30 | I23: 44755 | J23: 44772 | M23: Generado documento | N23: 1 | O23: 1 | P23: 0 | Q23: 1 | R23: 0 | S23: 13147 | T23: 13147 | U23: USD | V23: 233A7202-3 | W23: THE BOEING COMPANY | X23: 7218|S22B04_S1076 | Y23: 8990 | AA23: 1 | AB23: 1 | AE23: 8000 | AF23: Pedido de materiales | AH23: ZNB | AK23: SRM2ERP | AL23: 0 | AN23: 0 | AO23: 1 | AQ23: 0 | AR23: BAE SYSTEMS | AS23: Simulacion | AV23: El Rayo (Polig Indust La Quinta,719171Cabanillas del Campo | AW23: '@FM@ | AX23: 44820 | AY23: 9008109 | BC23: 44772 | BH23: 322020 | BJ23: 13147 | BK23: 13147 | BN23: X | BO23: 20 | BP23: USD | BR23: USD | BS23: USD | BT23: María Ángeles Coello Roma | BZ23: 40 | CA23: 1 | CB23: 13147 | CD23: 1046021 | CH23: 0 | CI23: 0,96274 | CK23: Q | CL23: 8 | CM23: 0.00 | CQ23: UN | CR23: UN | CS23: UN | CT23: UN | CU23: UN | CV23: UN | CW23: UN | CX23: 0 | CZ23: 0 | DA23: 13147.00 | DB23: 13147 | DC23: 0 | DD23: 13147 | DE23: 0 | DF23: ACOELLO | DG23: Ramos Torreadrado, Carolina
A24: 1390705170700 | B24: MOD ASSY-ENG/APU FIRE CONTROL P8-01 | C24: 44750 | D24: 1101516960 | E24: 4 | G24: 4200482994 | H24: 40 | I24: 44755 | J24: 44790 | M24: Generado documento | N24: 1 | O24: 1 | P24: 0 | Q24: 1 | R24: 0 | S24: 69459 | T24: 69459 | U24: USD | V24: 69-37307-300 | W24: THE BOEING COMPANY | X24: 7218|S22B04_S1076 | Y24: 8990 | AA24: 1 | AB24: 1 | AE24: 8000 | AF24: Pedido de materiales | AH24: ZNB | AJ24: 491051 | AK24: SRM2ERP | AL24: 0 | AN24: 0 | AO24: 1 | AQ24: 0 | AR24: BAE SYSTEMS | AS24: Simulacion | AV24: El Rayo (Polig Indust La Quinta,719171Cabanillas del Campo | AW24: '@FM@ | AX24: 44820 | AY24: 9008109 | BC24: 44790 | BH24: 322020 | BJ24: 69459 | BK24: 69459 | BN24: X | BO24: 20 | BP24: USD | BR24: USD | BS24: USD | BT24: María Ángeles Coello Roma | BZ24: 40 | CA24: 1 | CB24: 69459 | CD24: 1046021 | CH24: 0 | CI24: 0,96274 | CK24: Q | CL24: 8 | CM24: 0.00 | CQ24: UN | CR24: UN | CS24: UN | CT24: UN | CU24: UN | CV24: UN | CW24: UN | CX24: 0 | CZ24: 0 | DA24: 69459.00 | DB24: 69459 | DC24: 0 | DD24: 69459 | DE24: 0 | DF24: ACOELLO | DG24: Ramos Torreadrado, Carolina
A25: 1390705170800 | B25: MOD ASSY-RUD TRIM P8-43 | C25: 44750 | D25: 1101516960 | E25: 5 | G25: 4200482994 | H25: 50 | I25: 44755 | J25: 44772 | M25: Generado documento | N25: 1 | O25: 1 | P25: 0 | Q25: 1 | R25: 0 | S25: 17005 | T25: 17005 | U25: USD | V25: 69-73703-313 | W25: THE BOEING COMPANY | X25: 7218|S22B04_S1076 | Y25: 8990 | AA25: 1 | AB25: 1 | AE25: 8000 | AF25: Pedido de materiales | AH25: ZNB | AJ25: 491051 | AK25: SRM2ERP | AL25: 0 | AN25: 0 | AO25: 1 | AQ25: 0 | AR25: BAE SYSTEMS | AS25: Simulacion | AV25: El Rayo (Polig Indust La Quinta,719171Cabanillas del Campo | AW25: '@FM@ | AX25: 44820 | AY25: 9008109 | BB25: 44753 | BC25: 44772 | BF25: 44753 | BH25: 322020 | BJ25: 17005 | BK25: 17005 | BN25: X | BO25: 20 | BP25: USD | BR25: USD | BS25: USD | BT25: María Ángeles Coello Roma | BZ25: 40 | CA25: 1 | CB25: 17005 | CD25: 1046021 | CH25: 0 | CI25: 0,96274 | CK25: Q | CL25: 8 | CM25: 0.00 | CQ25: UN | CR25: UN | CS25: UN | CT25: UN | CU25: UN | CV25: UN | CW25: UN | CX25: 0 | CZ25: 0 | DA25: 17005.00 | DB25: 17005 | DC25: 0 | DD25: 17005 | DE25: 0 | DF25: ACOELLO | DG25: Ramos Torreadrado, Carolina
A26: 1390705170900 | B26: MOD ASSY-FLOOD AND PNL LIGHTING P8-50 | C26: 44750 | D26: 1101516960 | E26: 6 | G26: 4200482994 | H26: 60 | I26: 44755 | J26: 44772 | M26: Generado documento | N26: 1 | O26: 1 | P26: 0 | Q26: 1 | R26: 0 | S26: 10111 | T26: 10111 | U26: USD | V26: 69-76435-305 | W26: THE BOEING COMPANY | X26: 7218|S22B04_S1076 | Y26: 8990 | AA26: 1 | AB26: 1 | AE26: 8000 | AF26: Pedido de materiales | AH26: ZNB | AJ26: 491051 | AK26: SRM2ERP | AL26: 0 | AN26: 0 | AO26: 1 | AQ26: 0 | AR26: BAE SYSTEMS | AS26: Simulacion | AV26: El Rayo (Polig Indust La Quinta,719171Cabanillas del Campo | AW26: '@FM@ | AX26: 44820 | AY26: 9008109 | BB26: 44753 | BC26: 44772 | BF26: 44753 | BH26: 322020 | BJ26: 10111 | BK26: 10111 | BN26: X | BO26: 20 | BP26: USD | BR26: USD | BS26: USD | BT26: María Ángeles Coello Roma | BZ26: 40 | CA26: 1 | CB26: 10111 | CD26: 1046021 | CH26: 0 | CI26: 0,96274 | CK26: Q | CL26: 8 | CM26: 0.00 | CQ26: UN | CR26: UN | CS26: UN | CT26: UN | CU26: UN | CV26: UN | CW26: UN | CX26: 0 | CZ26: 0 | DA26: 10111.00 | DB26: 10111 | DC26: 0 | DD26: 10111 | DE26: 0 | DF26: ACOELLO | DG26: Ramos Torreadrado, Carolina
A27: 1390705171200 | B27: MOD ASSY ENGINE AND WING ANTI-ICE P5-11 | C27: 44750 | D27: 1101516960 | E27: 7 | G27: 4200482994 | H27: 70 | I27: 44755 | J27: 44972 | M27: Generado documento | N27: 1 | O27: 1 | P27: 0 | Q27: 1 | R27: 0 | S27: 47060 | T27: 47060 | U27: USD | V27: 69-37320-3114 | W27: THE BOEING COMPANY | X27: 7218|S22B04_S1076 | Y27: 8990 | AA27: 1 | AB27: 1 | AE27: 8000 | AF27: Pedido de materiales | AH27: ZNB | AJ27: 491051 | AK27: SRM2ERP | AL27: 0 | AN27: 0 | AO27: 1 | AQ27: 0 | AR27: BAE SYSTEMS | AS27: Simulacion | AV27: El Rayo (Polig Indust La Quinta,719171Cabanillas del Campo | AW27: '@FM@ | AX27: 44820 | AY27: 9008109 | BB27: 44753 | BC27: 44972 | BF27: 44753 | BH27: 322020 | BJ27: 47060 | BK27: 47060 | BN27: X | BO27: 20 | BP27: USD | BR27: USD | BS27: USD | BT27: María Ángeles Coello Roma | BZ27: 40 | CA27: 1 | CB27: 47060 | CD27: 1046021 | CH27: 0 | CI27: 0,96274 | CK27: Q | CL27: 8 | CM27: 0.00 | CQ27: UN | CR27: UN | CS27: UN | CT27: UN | CU27: UN | CV27: UN | CW27: UN | CX27: 0 | CZ27: 0 | DA27: 47060.00 | DB27: 47060 | DC27: 0 | DD27: 47060 | DE27: 0 | DF27: ACOELLO | DG27: Ramos Torreadrado, Carolina
A28: 1390702790100 | B28: COCKPIT SPEAKER ASSY | C28: 44750 | D28: 1101517004 | E28: 1 | G28: 4200482968 | H28: 10 | I28: 44755 | J28: 44827 | M28: Liberado | N28: 2 | O28: 2 | P28: 0 | Q28: 2 | R28: 0 | S28: 3612.12 | T28: 7224.24 | U28: EUR | V28: 10-62090-30 | W28: EUROPAVIA ESPAÑA S.A. | X28: 7218|S22B04_S1076 | Y28: 8990 | AA28: 1 | AB28: 1 | AE28: 8000 | AF28: Pedido de materiales | AH28: ZNB | AJ28: 420046 | AK28: SRM2ERP | AL28: 0 | AN28: 0 | AO28: 2 | AQ28: 0 | AR28: AVTECH CORPORATION | AS28: Simulacion | AV28: El Rayo (Polig Indust La Quinta,719171Cabanillas del Campo | AW28: '@FM@ | AX28: 44820 | AY28: 9010466 | BC28: 44827 | BH28: 322010 | BJ28: 7224.24 | BK28: 3612.12 | BN28: 3 | BO28: 20 | BP28: EUR | BR28: EUR | BS28: EUR | BT28: María Ángeles Coello Roma | BZ28: 17 | CA28: 2 | CB28: 7224.24 | CD28: 1009691 | CH28: 0 | CI28: 1,00000 | CK28: Q | CL28: 8 | CM28: 0.00 | CQ28: UN | CR28: UN | CS28: UN | CT28: UN | CU28: UN | CV28: UN | CW28: UN | CX28: 0 | CZ28: 0 | DA28: 7224.24 | DB28: 7224.24 | DC28: 0 | DD28: 7224.24 | DE28: 0 | DF28: ACOELLO | DG28: Aguado Blanco, Ana María
B29: INSTALLATION ASISTANCE | C29: 44749 | D29: 1101516535 | E29: 1 | G29: 4300285652 | H29: 10 | I29: 44750 | J29: 45026 | M29: Liberado | N29: 1 | O29: 1 | P29: 0 | Q29: 0 | R29: 0 | S29: 5200 | T29: 5200 | U29: EUR | W29: MOOG, B.V. | X29: 7218|S22B04_S107E | AA29: 1 | AB29: 1 | AE29: 8000 | AF29: Ped. cerrado servic. | AH29: ZSE1 | AJ29: 491051 | AK29: SRM2ERP | AL29: 0 | AN29: 0 | AO29: 1 | AQ29: 0 | AS29: Simulacion | AV29: Calle Mar Egeo,428830San Fernando de Henares | AW29: '@FM@ | AX29: 44834 | BC29: 45026 | BH29: 721519 | BJ29: 5200 | BK29: 5200 | BN29: 3 | BO29: 20 | BP29: EUR | BR29: EUR | BS29: EUR | BT29: María Ángeles Coello Roma | BZ29: 0 | CA29: 1 | CB29: 5200 | CD29: 1052878 | CH29: 0 | CI29: 1,00000 | CJ29: PO | CK29: P | CL29: 0 | CM29: 0.00 | CQ29: UA | CR29: UA | CS29: N/A | CT29: N/A | CV29: UA | CW29: UA | CX29: 0 | CZ29: 0 | DA29: 5200.00 | DB29: 5200 | DC29: 0 | DD29: 5200 | DE29: 0 | DF29: ACOELLO | DG29: Ramos Torreadrado, Carolina
B30: TUNING | C30: 44749 | D30: 1101516535 | E30: 2 | G30: 4300285652 | H30: 20 | I30: 44750 | J30: 45107 | M30: Liberado | N30: 1 | O30: 1 | P30: 0 | Q30: 0 | R30: 0 | S30: 6560 | T30: 6560 | U30: EUR | W30: MOOG, B.V. | X30: 7218|S22B04_S107E | AA30: 1 | AB30: 1 | AE30: 8000 | AF30: Ped. cerrado servic. | AH30: ZSE1 | AJ30: SRM2ERP | AK30: SRM2ERP | AL30: 0 | AN30: 0 | AO30: 1 | AQ30: 0 | AS30: Simulacion | AV30: Calle Mar Egeo,428830San Fernando de Henares | AW30: '@FM@ | AX30: 44834 | BB30: 44749 | BC30: 45107 | BF30: 44749 | BH30: 721519 | BJ30: 6560 | BK30: 6560 | BN30: 3 | BO30: 20 | BP30: EUR | BR30: EUR | BS30: EUR | BT30: María Ángeles Coello Roma | BZ30: 0 | CA30: 1 | CB30: 6560 | CD30: 1052878 | CH30: 0 | CI30: 1,00000 | CJ30: PO | CK30: P | CL30: 0 | CM30: 0.00 | CQ30: UA | CR30: UA | CS30: N/A | CT30: N/A | CV30: UA | CW30: UA | CX30: 0 | CZ30: 0 | DA30: 6560.00 | DB30: 6560 | DC30: 0 | DD30: 6560 | DE30: 0 | DF30: ACOELLO | DG30: Ramos Torreadrado, Carolina
A31: 1390705333000 | B31: DISPOSITIVO SIMULACION VISUAL IG + WXR | C31: 44747 | D31: 1101515529 | E31: 1 | G31: 4200482135 | H31: 10 | I31: 44748 | J31: 44810 | K31: X | M31: Liberado | N31: 1 | O31: 1 | P31: 0 | Q31: 1 | R31: 0 | S31: 663598 | T31: 663598 | U31: GBP | V31: 946-00C6-100_REVD EP-8100 | W31: ROCKWELL COLLINS UK LTD | X31: 7218|S22B04_P1023311 | Y31: 8990 | AA31: 1 | AB31: 1 | AE31: 8000 | AF31: Pedido de materiales | AH31: ZNB | AK31: SRM2ERP | AL31: 0 | AN31: 0 | AO31: 1 | AQ31: 0 | AR31: ROCKWELL-COLLINS | AS31: Simulacion | AV31: El Rayo (Polig Indust La Quinta,719171Cabanillas del Campo | AW31: '@FM@ | AX31: 44810 | AY31: 9000328 | BC31: 44810 | BH31: 322020 | BJ31: 663598 | BK31: 663598 | BN31: 3 | BO31: 20 | BP31: GBP | BR31: GBP | BS31: GBP | BT31: María Ángeles Coello Roma | BZ31: 40 | CA31: 1 | CB31: 663598 | CD31: 1051399 | CH31: 0 | CI31: 1,16523 | CJ31: PO | CK31: Q | CL31: 8 | CM31: 0.00 | CQ31: UN | CR31: UN | CS31: UN | CT31: UN | CU31: UN | CV31: UN | CW31: UN | CX31: 0 | CZ31: 0 | DA31: 663598.00 | DB31: 663598 | DC31: 0 | DD31: 663598 | DE31: 0 | DF31: ACOELLO | DG31: Ramos Torreadrado, Carolina
A32: 1390705330000 | B32: HUD COMPUTER B737 | C32: 44740 | D32: 1101513085 | E32: 1 | G32: 4200482123 | H32: 10 | I32: 44748 | J32: 45075 | M32: Liberado | N32: 1 | O32: 1 | P32: 0 | Q32: 1 | R32: 0 | S32: 169524 | T32: 169524 | U32: USD | V32: 1500-2460-004 | W32: ROCKWELL COLLINS UK LTD | X32: 7218|S22B04_S1076 | Y32: 6990 | AA32: 1 | AB32: 1 | AE32: 6000 | AF32: Pedido de materiales | AH32: ZNB | AJ32: 491051 | AK32: SRM2ERP | AL32: 0 | AN32: 0 | AO32: 1 | AQ32: 0 | AR32: ROCKWELL-COLLINS | AS32: Simulacion | AV32: El Rayo (Polig Indust La Quinta,719171Cabanillas del Campo | AW32: '@FM@ | AX32: 45075 | AY32: 9000328 | BC32: 45075 | BH32: 322010 | BJ32: 169524 | BK32: 169524 | BN32: 3 | BO32: 20 | BP32: USD | BR32: USD | BS32: USD | BT32: María Isabel Recio Gutiérrez | BZ32: 40 | CA32: 1 | CB32: 169524 | CD32: 1051399 | CH32: 0 | CI32: 0,96274 | CJ32: PO | CK32: Q | CL32: 8 | CM32: 0.00 | CQ32: UN | CR32: UN | CS32: UN | CT32: UN | CU32: UN | CV32: UN | CW32: UN | CX32: 0 | CZ32: 0 | DA32: 169524.00 | DB32: 169524 | DC32: 0 | DD32: 169524 | DE32: 0 | DF32: MRECIO | DG32: Ramos Torreadrado, Carolina
A33: 1390705320000 | B33: HUD OVERHEAD UNIT | C33: 44740 | D33: 1101513085 | E33: 2 | G33: 4200482123 | H33: 20 | I33: 44748 | J33: 45075 | M33: Liberado | N33: 1 | O33: 1 | P33: 0 | Q33: 1 | R33: 0 | S33: 296068 | T33: 296068 | U33: USD | V33: 1500-2360-001 | W33: ROCKWELL COLLINS UK LTD | X33: 7218|S22B04_S1076 | Y33: 6990 | AA33: 1 | AB33: 1 | AE33: 6000 | AF33: Pedido de materiales | AH33: ZNB | AJ33: 491051 | AK33: SRM2ERP | AL33: 0 | AN33: 0 | AO33: 1 | AQ33: 0 | AR33: ROCKWELL-COLLINS | AS33: Simulacion | AV33: El Rayo (Polig Indust La Quinta,719171Cabanillas del Campo | AX33: 45075 | AY33: 9000328 | BC33: 45075 | BH33: 322010 | BJ33: 296068 | BK33: 296068 | BN33: 3 | BO33: 20 | BP33: USD | BR33: USD | BS33: USD | BT33: María Isabel Recio Gutiérrez | BZ33: 40 | CA33: 1 | CB33: 296068 | CD33: 1051399 | CH33: 0 | CI33: 0,96274 | CJ33: PO | CK33: Q | CL33: 8 | CM33: 0.00 | CQ33: UN | CR33: UN | CS33: UN | CT33: UN | CU33: UN | CV33: UN | CW33: UN | CX33: 0 | CZ33: 0 | DA33: 296068.00 | DB33: 296068 | DC33: 0 | DD33: 296068 | DE33: 0 | DF33: MRECIO | DG33: Ramos Torreadrado, Carolina
A34: 1390704460200 | B34: SIMULADOR PANEL CTR SIMMMR 737 PLUG&PLAY | C34: 44735 | D34: 1101511711 | E34: 1 | G34: 4200482272 | H34: 10 | I34: 44749 | J34: 44798 | M34: Generado documento | N34: 2 | O34: 2 | P34: 0 | Q34: 2 | R34: 0 | S34: 23000 | T34: 46000 | U34: USD | V34: C01-2200-321 | W34: THE BOEING COMPANY | X34: 7218|S22B04_S1076 | Y34: 6990 | AA34: 1 | AB34: 1 | AE34: 6000 | AF34: Pedido de materiales | AH34: ZNB | AJ34: 491051 | AK34: SRM2ERP | AL34: 0 | AN34: 0 | AO34: 2 | AQ34: 0 | AR34: BOEING | AS34: Simulacion | AV34: El Rayo (Polig Indust La Quinta,719171Cabanillas del Campo | AW34: '@FM@ | AX34: 44798 | AY34: 9000332 | BB34: 44739 | BC34: 44798 | BF34: 44739 | BH34: 322010 | BJ34: 31800 | BK34: 15900 | BN34: X | BO34: 20 | BP34: USD | BR34: USD | BS34: USD | BT34: María Isabel Recio Gutiérrez | BZ34: 40 | CA34: 2 | CB34: 46000 | CD34: 1046021 | CH34: 0 | CI34: 0,96274 | CJ34: PO | CK34: Q | CL34: 8 | CM34: 0.00 | CQ34: UN | CR34: UN | CS34: UN | CT34: UN | CU34: UN | CV34: UN | CW34: UN | CX34: 0 | CZ34: 0 | DA34: 46000.00 | DB34: 46000 | DC34: 0 | DD34: 46000 | DE34: 0 | DF34: MRECIO | DG34: Ramos Torreadrado, Carolina
A35: 1390705340000 | B35: PANEL SINTONIZACION RADIO SIMULA 737 | C35: 44735 | D35: 1101511711 | E35: 2 | G35: 4200482272 | H35: 20 | I35: 44749 | J35: 44798 | M35: Generado documento | N35: 2 | O35: 2 | P35: 0 | Q35: 2 | R35: 0 | S35: 15600 | T35: 31200 | U35: USD | V35: C01-1600-321 | W35: THE BOEING COMPANY | X35: 7218|S22B04_S1076 | Y35: 6990 | AA35: 1 | AB35: 1 | AE35: 6000 | AF35: Pedido de materiales | AH35: ZNB | AJ35: 491051 | AK35: SRM2ERP | AL35: 0 | AN35: 0 | AO35: 2 | AQ35: 0 | AR35: BOEING | AS35: Simulacion | AV35: El Rayo (Polig Indust La Quinta,719171Cabanillas del Campo | AW35: '@FM@ | AX35: 44848 | AY35: 9000332 | BB35: 44739 | BC35: 44798 | BF35: 44774 | BH35: 322010 | BJ35: 31200 | BK35: 15600 | BN35: X | BO35: 20 | BP35: USD | BR35: USD | BS35: USD | BT35: María Isabel Recio Gutiérrez | BZ35: 40 | CA35: 2 | CB35: 31200 | CD35: 1046021 | CH35: 0 | CI35: 0,96274 | CJ35: PO | CK35: Q | CL35: 8 | CM35: 0.00 | CQ35: UN | CR35: UN | CS35: UN | CT35: UN | CU35: UN | CV35: UN | CW35: UN | CX35: 0 | CZ35: 0 | DA35: 31200.00 | DB35: 31200 | DC35: 0 | DD35: 31200 | DE35: 0 | DF35: MRECIO | DG35: Ramos Torreadrado, Carolina
A36: 1390704460300 | B36: SIMULADOR 737NG SIMEFIS PLUG-AND-PLAY | C36: 44735 | D36: 1101511711 | E36: 3 | G36: 4200482272 | H36: 30 | I36: 44749 | J36: 45152 | M36: Generado documento | N36: 2 | O36: 2 | P36: 0 | Q36: 2 | R36: 0 | S36: 23300 | T36: 46600 | U36: USD | V36: C01-1300-322 | W36: THE BOEING COMPANY | X36: 7218|S22B04_S1076 | Y36: 6990 | AA36: 1 | AB36: 1 | AE36: 6000 | AF36: Pedido de materiales | AH36: ZNB | AJ36: 491051 | AK36: SRM2ERP | AL36: 0 | AN36: 0 | AO36: 2 | AQ36: 0 | AR36: BOEING | AS36: Simulacion | AV36: El Rayo (Polig Indust La Quinta,719171Cabanillas del Campo | AW36: '@FM@ | AX36: 45134 | AY36: 9000332 | BB36: 44739 | BC36: 45152 | BF36: 45062 | BH36: 322010 | BJ36: 46600 | BK36: 23300 | BN36: X | BO36: 20 | BP36: USD | BR36: USD | BS36: USD | BT36: María Isabel Recio Gutiérrez | BZ36: 40 | CA36: 2 | CB36: 46600 | CD36: 1046021 | CH36: 0 | CI36: 0,96274 | CJ36: PO | CK36: Q | CL36: 8 | CM36: 0.00 | CQ36: UN | CR36: UN | CS36: UN | CT36: UN | CU36: UN | CV36: UN | CW36: UN | CX36: 0 | CZ36: 0 | DA36: 46600.00 | DB36: 46600 | DC36: 0 | DD36: 46600 | DE36: 0 | DF36: MRECIO | DG36: Ramos Torreadrado, Carolina
B37: SOLICITUD NORMA IEC 62443-4-2 | C37: 44734 | D37: 1101511444 | E37: 1 | G37: 4300285002 | H37: 10 | I37: 44740 | J37: 44834 | M37: Liberado | N37: 1 | O37: 1 | P37: 0 | Q37: 0 | R37: 0 | S37: 1000 | T37: 1000 | U37: USD | W37: IHS MARKIT GLOBAL SARL | X37: 7218|S22B04_GPR05 | AA37: 1 | AB37: 1 | AE37: 6000 | AF37: Ped. cerrado servic. | AH37: ZSE1 | AJ37: 152074 | AK37: SRM2ERP | AL37: 0 | AN37: 0 | AO37: 1 | AQ37: 0 | AS37: Simulacion | AV37: Calle Mar Egeo,428830San Fernando de Henares | AW37: '@FM@ | AX37: 44741 | BB37: 44736 | BC37: 44834 | BF37: 44736 | BH37: 651015 | BJ37: 1000 | BK37: 1000 | BN37: 3 | BO37: 20 | BP37: USD | BR37: USD | BS37: USD | BT37: María Isabel Recio Gutiérrez | BZ37: 0 | CA37: 1 | CB37: 1000 | CD37: 1222355 | CH37: 0 | CI37: 0,93345 | CJ37: PO | CK37: P | CL37: 0 | CM37: 1000.00 | CQ37: UA | CR37: UA | CS37: N/A | CT37: N/A | CV37: UA | CW37: UA | CX37: 0 | CZ37: 0 | DA37: 0.00 | DB37: 1000 | DC37: 0 | DD37: 0 | DE37: 1000 | DF37: MRECIO | DG37: Fernández Fernández, María
